Workbook

Sheet Sales Data
A1: Order ID | B1: Order Date | C1: Region | D1: Product | E1: Category | F1: Sales | G1: Profit | H1: Quantity | I1: Profit Margin | J1: Sales Category
A2: ORD-100437 | B2: 2024-01-03 | C2: North | D2: Whiteboard | E2: Stationery | F2: 1782.8 | G2: 335.64 | H2: 5 | I2: =IFERROR(G2/F2,0) -> 0.18826565 | J2: =IF(F2>5000,"High",IF(F2>1500,"Medium","Low")) -> Medium
A3: ORD-100591 | B3: 2024-01-04 | C3: North | D3: Wall Clock | E3: Home & Office | F3: 721.48 | G3: 190.89 | H3: 2 | I3: =IFERROR(G3/F3,0) -> 0.26458114 | J3: =IF(F3>5000,"High",IF(F3>1500,"Medium","Low")) -> Low
A4: ORD-100844 | B4: 2024-01-04 | C4: East | D4: Whiteboard | E4: Stationery | F4: 776.1 | G4: 230.54 | H4: 2 | I4: =IFERROR(G4/F4,0) -> 0.29704935 | J4: =IF(F4>5000,"High",IF(F4>1500,"Medium","Low")) -> Low
A5: ORD-100288 | B5: 2024-01-04 | C5: South | D5: LED Monitor | E5: Electronics | F5: 206.2 | G5: 53.57 | H5: 2 | I5: =IFERROR(G5/F5,0) -> 0.25979631 | J5: =IF(F5>5000,"High",IF(F5>1500,"Medium","Low")) -> Low
A6: ORD-100426 | B6: 2024-01-05 | C6: East | D6: Bookshelf | E6: Furniture | F6: 316.87 | G6: 57.05 | H6: 1 | I6: =IFERROR(G6/F6,0) -> 0.18004229 | J6: =IF(F6>5000,"High",IF(F6>1500,"Medium","Low")) -> Low
A7: ORD-100783 | B7: 2024-01-05 | C7: South | D7: Whiteboard | E7: Stationery | F7: 2272.14 | G7: 621.5 | H7: 6 | I7: =IFERROR(G7/F7,0) -> 0.27353068 | J7: =IF(F7>5000,"High",IF(F7>1500,"Medium","Low")) -> Medium
A8: ORD-100763 | B8: 2024-01-06 | C8: West | D8: Wall Clock | E8: Home & Office | F8: 1933.2 | G8: 602.05 | H8: 5 | I8: =IFERROR(G8/F8,0) -> 0.31142665 | J8: =IF(F8>5000,"High",IF(F8>1500,"Medium","Low")) -> Medium
A9: ORD-100782 | B9: 2024-01-06 | C9: North | D9: Printer | E9: Electronics | F9: 2146.32 | G9: 491.16 | H9: 6 | I9: =IFERROR(G9/F9,0) -> 0.2288382 | J9: =IF(F9>5000,"High",IF(F9>1500,"Medium","Low")) -> Medium
A10: ORD-100280 | B10: 2024-01-06 | C10: South | D10: LED Monitor | E10: Electronics | F10: 580.56 | G10: 125.25 | H10: 6 | I10: =IFERROR(G10/F10,0) -> 0.21573998 | J10: =IF(F10>5000,"High",IF(F10>1500,"Medium","Low")) -> Low
A11: ORD-100059 | B11: 2024-01-08 | C11: West | D11: Coffee Maker | E11: Home & Office | F11: 1807.2 | G11: 413.07 | H11: 5 | I11: =IFERROR(G11/F11,0) -> 0.22856906 | J11: =IF(F11>5000,"High",IF(F11>1500,"Medium","Low")) -> Medium
A12: ORD-100460 | B12: 2024-01-09 | C12: West | D12: Office Chair | E12: Furniture | F12: 283.94 | G12: 123.21 | H12: 1 | I12: =IFERROR(G12/F12,0) -> 0.4339297 | J12: =IF(F12>5000,"High",IF(F12>1500,"Medium","Low")) -> Low
A13: ORD-100050 | B13: 2024-01-09 | C13: North | D13: Laptop Stand | E13: Electronics | F13: 105.17 | G13: 29.73 | H13: 1 | I13: =IFERROR(G13/F13,0) -> 0.28268518 | J13: =IF(F13>5000,"High",IF(F13>1500,"Medium","Low")) -> Low
... A851: ORD-100268 | B851: 2024-12-28 | C851: West | D851: Standing Desk | E851: Furniture | F851: 511.72 | G851: 190.04 | H851: 4 | I851: =IFERROR(G851/F851,0) -> 0.37137497 | J851: =IF(F851>5000,"High",IF(F851>1500,"Medium","Low")) -> Low

Sheet KPI Summary
B2: Management-Level Sales Performance Dashboard
B3: KPI Summary — Business Snapshot (Task 2)
B5: Total Sales | E5: Total Profit | H5: Average Profit Margin | K5: Total Quantity Sold
B6: =SUM('Sales Data'!F2:F851) -> 653618.69 | E6: =SUM('Sales Data'!G2:G851) -> 205558.67 | H6: =AVERAGE('Sales Data'!I2:I851) -> 0.31299662 | K6: =SUM('Sales Data'!H2:H851) -> 2506
B9: Sales & Profit by Region
B10: Region | C10: Total Sales | D10: Total Profit | E10: Profit Margin
B11: North | C11: =SUMIFS('Sales Data'!$F$2:$F$851,'Sales Data'!$C$2:$C$851,B11) -> 174536.95 | D11: =SUMIFS('Sales Data'!$G$2:$G$851,'Sales Data'!$C$2:$C$851,B11) -> 54686.95 | E11: =IFERROR(D11/C11,0) -> 0.31332592
B12: South | C12: =SUMIFS('Sales Data'!$F$2:$F$851,'Sales Data'!$C$2:$C$851,B12) -> 137335.37 | D12: =SUMIFS('Sales Data'!$G$2:$G$851,'Sales Data'!$C$2:$C$851,B12) -> 43195.94 | E12: =IFERROR(D12/C12,0) -> 0.31452888
B13: East | C13: =SUMIFS('Sales Data'!$F$2:$F$851,'Sales Data'!$C$2:$C$851,B13) -> 179307.85 | D13: =SUMIFS('Sales Data'!$G$2:$G$851,'Sales Data'!$C$2:$C$851,B13) -> 57573.52 | E13: =IFERROR(D13/C13,0) -> 0.32108756
B14: West | C14: =SUMIFS('Sales Data'!$F$2:$F$851,'Sales Data'!$C$2:$C$851,B14) -> 162438.52 | D14: =SUMIFS('Sales Data'!$G$2:$G$851,'Sales Data'!$C$2:$C$851,B14) -> 50102.26 | E14: =IFERROR(D14/C14,0) -> 0.30843829
B17: Sales & Profit by Category
B18: Category | C18: Total Sales | D18: Total Profit | E18: Profit Margin
B19: Electronics | C19: =SUMIFS('Sales Data'!$F$2:$F$851,'Sales Data'!$E$2:$E$851,B19) -> 154137.95 | D19: =SUMIFS('Sales Data'!$G$2:$G$851,'Sales Data'!$E$2:$E$851,B19) -> 48768.14 | E19: =IFERROR(D19/C19,0) -> 0.31639282
B20: Furniture | C20: =SUMIFS('Sales Data'!$F$2:$F$851,'Sales Data'!$E$2:$E$851,B20) -> 175844.81 | D20: =SUMIFS('Sales Data'!$G$2:$G$851,'Sales Data'!$E$2:$E$851,B20) -> 67418.11 | E20: =IFERROR(D20/C20,0) -> 0.38339551
B21: Home & Office | C21: =SUMIFS('Sales Data'!$F$2:$F$851,'Sales Data'!$E$2:$E$851,B21) -> 150958.17 | D21: =SUMIFS('Sales Data'!$G$2:$G$851,'Sales Data'!$E$2:$E$851,B21) -> 38092.71 | E21: =IFERROR(D21/C21,0) -> 0.25233951
B22: Stationery | C22: =SUMIFS('Sales Data'!$F$2:$F$851,'Sales Data'!$E$2:$E$851,B22) -> 172677.76 | D22: =SUMIFS('Sales Data'!$G$2:$G$851,'Sales Data'!$E$2:$E$851,B22) -> 51279.71 | E22: =IFERROR(D22/C22,0) -> 0.29696766
B25: Monthly Sales Trend
B26: Month | C26: Total Sales | D26: Total Profit
B27: Jan | C27: =SUMPRODUCT(('Sales Data'!$F$2:$F$851)*(MONTH('Sales Data'!$B$2:$B$851)=1)) -> 41463.68 | D27: =SUMPRODUCT(('Sales Data'!$G$2:$G$851)*(MONTH('Sales Data'!$B$2:$B$851)=1)) -> 12137.72
B28: Feb | C28: =SUMPRODUCT(('Sales Data'!$F$2:$F$851)*(MONTH('Sales Data'!$B$2:$B$851)=2)) -> 49078.13 | D28: =SUMPRODUCT(('Sales Data'!$G$2:$G$851)*(MONTH('Sales Data'!$B$2:$B$851)=2)) -> 15390.46
B29: Mar | C29: =SUMPRODUCT(('Sales Data'!$F$2:$F$851)*(MONTH('Sales Data'!$B$2:$B$851)=3)) -> 60837.36 | D29: =SUMPRODUCT(('Sales Data'!$G$2:$G$851)*(MONTH('Sales Data'!$B$2:$B$851)=3)) -> 19540.36
B30: Apr | C30: =SUMPRODUCT(('Sales Data'!$F$2:$F$851)*(MONTH('Sales Data'!$B$2:$B$851)=4)) -> 61162.97 | D30: =SUMPRODUCT(('Sales Data'!$G$2:$G$851)*(MONTH('Sales Data'!$B$2:$B$851)=4)) -> 18841.65
B31: May | C31: =SUMPRODUCT(('Sales Data'!$F$2:$F$851)*(MONTH('Sales Data'!$B$2:$B$851)=5)) -> 51164.38 | D31: =SUMPRODUCT(('Sales Data'!$G$2:$G$851)*(MONTH('Sales Data'!$B$2:$B$851)=5)) -> 15473.48
B32: Jun | C32: =SUMPRODUCT(('Sales Data'!$F$2:$F$851)*(MONTH('Sales Data'!$B$2:$B$851)=6)) -> 60837.29 | D32: =SUMPRODUCT(('Sales Data'!$G$2:$G$851)*(MONTH('Sales Data'!$B$2:$B$851)=6)) -> 18995.82
B33: Jul | C33: =SUMPRODUCT(('Sales Data'!$F$2:$F$851)*(MONTH('Sales Data'!$B$2:$B$851)=7)) -> 32762.88 | D33: =SUMPRODUCT(('Sales Data'!$G$2:$G$851)*(MONTH('Sales Data'!$B$2:$B$851)=7)) -> 10303.31
B34: Aug | C34: =SUMPRODUCT(('Sales Data'!$F$2:$F$851)*(MONTH('Sales Data'!$B$2:$B$851)=8)) -> 60321.28 | D34: =SUMPRODUCT(('Sales Data'!$G$2:$G$851)*(MONTH('Sales Data'!$B$2:$B$851)=8)) -> 21148.36
B35: Sep | C35: =SUMPRODUCT(('Sales Data'!$F$2:$F$851)*(MONTH('Sales Data'!$B$2:$B$851)=9)) -> 66124.54 | D35: =SUMPRODUCT(('Sales Data'!$G$2:$G$851)*(MONTH('Sales Data'!$B$2:$B$851)=9)) -> 19740.42
B36: Oct | C36: =SUMPRODUCT(('Sales Data'!$F$2:$F$851)*(MONTH('Sales Data'!$B$2:$B$851)=10)) -> 53614.56 | D36: =SUMPRODUCT(('Sales Data'!$G$2:$G$851)*(MONTH('Sales Data'!$B$2:$B$851)=10)) -> 17868.86
B37: Nov | C37: =SUMPRODUCT(('Sales Data'!$F$2:$F$851)*(MONTH('Sales Data'!$B$2:$B$851)=11)) -> 50917.3 | D37: =SUMPRODUCT(('Sales Data'!$G$2:$G$851)*(MONTH('Sales Data'!$B$2:$B$851)=11)) -> 15164.87
B38: Dec | C38: =SUMPRODUCT(('Sales Data'!$F$2:$F$851)*(MONTH('Sales Data'!$B$2:$B$851)=12)) -> 65334.32 | D38: =SUMPRODUCT(('Sales Data'!$G$2:$G$851)*(MONTH('Sales Data'!$B$2:$B$851)=12)) -> 20953.36
B41: Top 10 Products by Sales
B42: Rank | C42: Product | D42: Total Sales | E42: Total Profit
B43: 1 | C43: Coffee Maker | D43: =SUMIFS('Sales Data'!$F$2:$F$851,'Sales Data'!$D$2:$D$851,C43) -> 59306.87 | E43: =SUMIFS('Sales Data'!$G$2:$G$851,'Sales Data'!$D$2:$D$851,C43) -> 16123.71
B44: 2 | C44: Ballpoint Pen Pack | D44: =SUMIFS('Sales Data'!$F$2:$F$851,'Sales Data'!$D$2:$D$851,C44) -> 58616.82 | E44: =SUMIFS('Sales Data'!$G$2:$G$851,'Sales Data'!$D$2:$D$851,C44) -> 20219.47
B45: 3 | C45: Filing Cabinet | D45: =SUMIFS('Sales Data'!$F$2:$F$851,'Sales Data'!$D$2:$D$851,C45) -> 56713.38 | E45: =SUMIFS('Sales Data'!$G$2:$G$851,'Sales Data'!$D$2:$D$851,C45) -> 23439.3
B46: 4 | C46: Bluetooth Speaker | D46: =SUMIFS('Sales Data'!$F$2:$F$851,'Sales Data'!$D$2:$D$851,C46) -> 53113.09 | E46: =SUMIFS('Sales Data'!$G$2:$G$851,'Sales Data'!$D$2:$D$851,C46) -> 23045.3
B47: 5 | C47: Whiteboard | D47: =SUMIFS('Sales Data'!$F$2:$F$851,'Sales Data'!$D$2:$D$851,C47) -> 47787.53 | E47: =SUMIFS('Sales Data'!$G$2:$G$851,'Sales Data'!$D$2:$D$851,C47) -> 12372.68
B48: 6 | C48: Printer | D48: =SUMIFS('Sales Data'!$F$2:$F$851,'Sales Data'!$D$2:$D$851,C48) -> 46076.75 | E48: =SUMIFS('Sales Data'!$G$2:$G$851,'Sales Data'!$D$2:$D$851,C48) -> 10726.22
B49: 7 | C49: Wall Clock | D49: =SUMIFS('Sales Data'!$F$2:$F$851,'Sales Data'!$D$2:$D$851,C49) -> 44496.12 | E49: =SUMIFS('Sales Data'!$G$2:$G$851,'Sales Data'!$D$2:$D$851,C49) -> 11787.08
B50: 8 | C50: Desk Organizer | D50: =SUMIFS('Sales Data'!$F$2:$F$851,'Sales Data'!$D$2:$D$851,C50) -> 39711.87 | E50: =SUMIFS('Sales Data'!$G$2:$G$851,'Sales Data'!$D$2:$D$851,C50) -> 8384.67
...

Sheet Charts
B2: Trend & Performance Charts
